Workbook

Sheet 工作表1
A1: 公司類別 | B1: 年度 | C1: 月份 | D1: 合併事業群 | E1: 產品類別名稱 | F1: 實際營收 | G1: 五大產品線 | H1: 新事業群
A2: HQ | B2: 2026 | C2: 1 | D2: 網通+技鋼 | F2: 0 | G2: Server | H2: =_xlfn.XLOOKUP(TRIM(D2),對應!D:D,對應!E:E,"未對應") -> 1網通+技鋼
A3: HQ | B3: 2026 | C3: 2 | D3: 網通+技鋼 | F3: 0 | G3: Server | H3: =_xlfn.XLOOKUP(TRIM(D3),對應!D:D,對應!E:E,"未對應") -> 1網通+技鋼
A4: HQ | B4: 2025 | C4: 3 | D4: 通路方案 | E4: PSU | F4: 120150456 | G4: 專案電腦 | H4: =_xlfn.XLOOKUP(TRIM(D4),對應!D:D,對應!E:E,"未對應") -> 3通路方案
A5: HQ | B5: 2025 | C5: 3 | D5: 通路方案 | E5: DRAM | F5: 2218936 | G5: 主板 | H5: =_xlfn.XLOOKUP(TRIM(D5),對應!D:D,對應!E:E,"未對應") -> 3通路方案
A6: HQ | B6: 2025 | C6: 3 | D6: _其他 | E6: Other | F6: 75199082 | G6: Other | H6: =_xlfn.XLOOKUP(TRIM(D6),對應!D:D,對應!E:E,"未對應") -> 7製造
A7: HQ | B7: 2025 | C7: 5 | D7: _筆電+盈嘉 | E7: NB | F7: 495510617 | G7: 筆電 | H7: =_xlfn.XLOOKUP(TRIM(D7),對應!D:D,對應!E:E,"未對應") -> 4筆電+盈嘉
A8: HQ | B8: 2025 | C8: 5 | D8: 通路方案 | E8: CPU COOLER | F8: 17264793 | G8: 專案電腦 | H8: =_xlfn.XLOOKUP(TRIM(D8),對應!D:D,對應!E:E,"未對應") -> 3通路方案
A9: HQ | B9: 2025 | C9: 5 | D9: 通路方案 | E9: VGA | F9: 8429686114 | G9: 顯卡 | H9: =_xlfn.XLOOKUP(TRIM(D9),對應!D:D,對應!E:E,"未對應") -> 3通路方案
A10: HQ | B10: 2025 | C10: 6 | D10: 通路方案 | E10: PSU | F10: 88641153 | G10: 專案電腦 | H10: =_xlfn.XLOOKUP(TRIM(D10),對應!D:D,對應!E:E,"未對應") -> 3通路方案
A11: HQ | B11: 2025 | C11: 6 | D11: 通路方案 | E11: DRAM | F11: 10637843 | G11: 主板 | H11: =_xlfn.XLOOKUP(TRIM(D11),對應!D:D,對應!E:E,"未對應") -> 3通路方案
A12: HQ關係人交易 | B12: 2025 | C12: 1 | D12: 通路方案 | E12: MB | F12: -792843982 | G12: 主板 | H12: =_xlfn.XLOOKUP(TRIM(D12),對應!D:D,對應!E:E,"未對應") -> 3通路方案
A13: HQ關係人交易 | B13: 2025 | C13: 1 | D13: 通路方案 | E13: MM | F13: -29493 | G13: 主板 | H13: =_xlfn.XLOOKUP(TRIM(D13),對應!D:D,對應!E:E,"未對應") -> 3通路方案
A14: HQ關係人交易 | B14: 2025 | C14: 1 | D14: 通路方案 | E14: MM | F14: -230006 | G14: 主板 | H14: =_xlfn.XLOOKUP(TRIM(D14),對應!D:D,對應!E:E,"未對應") -> 3通路方案
A15: HQ關係人交易 | B15: 2025 | C15: 1 | D15: 通路方案 | E15: SSD | F15: -7655652 | G15: 主板 | H15: =_xlfn.XLOOKUP(TRIM(D15),對應!D:D,對應!E:E,"未對應") -> 3通路方案
... A265: HQ | B265: 2025 | C265: 9 | D265: 通路方案 | E265: MB | F265: 2561416464 | G265: 主板 | H265: =_xlfn.XLOOKUP(TRIM(D265),對應!D:D,對應!E:E,"未對應") -> 3通路方案
A266: RMA平台 | B266: 2025 | C266: 3 | D266: 百事益 | F266: 1860687 | G266: 百事益 | H266: =_xlfn.XLOOKUP(TRIM(D266),對應!D:D,對應!E:E,"未對應") -> 5百事益
A267: HQ關係人交易 | B267: 2025 | C267: 1 | D267: 通路方案 | E267: CPU COOLER | F267: -121052 | G267: 專案電腦 | H267: =_xlfn.XLOOKUP(TRIM(D267),對應!D:D,對應!E:E,"未對應") -> 3通路方案
A268: HQ關係人交易 | B268: 2025 | C268: 1 | D268: 通路方案 | E268: CPU COOLER | F268: -4825456 | G268: 專案電腦 | H268: =_xlfn.XLOOKUP(TRIM(D268),對應!D:D,對應!E:E,"未對應") -> 3通路方案
A269: HQ關係人交易 | B269: 2025 | C269: 1 | D269: 通路方案 | E269: PSU | F269: -1841324 | G269: 專案電腦 | H269: =_xlfn.XLOOKUP(TRIM(D269),對應!D:D,對應!E:E,"未對應") -> 3通路方案
A270: HQ關係人交易 | B270: 2025 | C270: 2 | D270: 通路方案 | E270: SSD | F270: -2220705 | G270: 主板 | H270: =_xlfn.XLOOKUP(TRIM(D270),對應!D:D,對應!E:E,"未對應") -> 3通路方案
A271: HQ關係人交易 | B271: 2025 | C271: 2 | D271: 通路方案 | E271: Case | F271: -4648 | G271: 專案電腦 | H271: =_xlfn.XLOOKUP(TRIM(D271),對應!D:D,對應!E:E,"未對應") -> 3通路方案
A272: HQ關係人交易 | B272: 2025 | C272: 2 | D272: 通路方案 | E272: Other | F272: -2366390 | G272: Other | H272: =_xlfn.XLOOKUP(TRIM(D272),對應!D:D,對應!E:E,"未對應") -> 3通路方案
A273: HQ關係人交易 | B273: 2025 | C273: 3 | D273: _其他 | E273: Other | F273: -419464 | G273: Other | H273: =_xlfn.XLOOKUP(TRIM(D273),對應!D:D,對應!E:E,"未對應") -> 7製造
A274: HQ關係人交易 | B274: 2025 | C274: 3 | D274: _其他 | E274: Other | F274: -6898800 | G274: Other | H274: =_xlfn.XLOOKUP(TRIM(D274),對應!D:D,對應!E:E,"未對應") -> 7製造
A275: HQ關係人交易 | B275: 2025 | C275: 1 | D275: 通路方案 | E275: PSU | F275: -4696086 | G275: 專案電腦 | H275: =_xlfn.XLOOKUP(TRIM(D275),對應!D:D,對應!E:E,"未對應") -> 3通路方案
A276: HQ關係人交易 | B276: 2025 | C276: 2 | D276: 通路方案 | E276: MB | F276: -654123447 | G276: 主板 | H276: =_xlfn.XLOOKUP(TRIM(D276),對應!D:D,對應!E:E,"未對應") -> 3通路方案
A277: HQ關係人交易 | B277: 2025 | C277: 2 | D277: 通路方案 | E277: MM | F277: -142126 | G277: 主板 | H277: =_xlfn.XLOOKUP(TRIM(D277),對應!D:D,對應!E:E,"未對應") -> 3通路方案
A278: HQ關係人交易 | B278: 2025 | C278: 2 | D278: _其他 | E278: Other | F278: -227860 | G278: Other | H278: =_xlfn.XLOOKUP(TRIM(D278),對應!D:D,對應!E:E,"未對應") -> 7製造
... A362: HQ | B362: 2025 | C362: 8 | D362: 通路方案 | E362: AI TOP | F362: 7636215 | G362: 專案電腦 | H362: =_xlfn.XLOOKUP(TRIM(D362),對應!D:D,對應!E:E,"未對應") -> 3通路方案
A363: RMA平台 | B363: 2025 | C363: 6 | D363: 百事益 | F363: 15990766 | G363: 百事益 | H363: =_xlfn.XLOOKUP(TRIM(D363),對應!D:D,對應!E:E,"未對應") -> 5百事益
A364: HQ關係人交易 | B364: 2025 | C364: 4 | D364: 通路方案 | E364: MB | F364: -1290305971 | G364: 主板 | H364: =_xlfn.XLOOKUP(TRIM(D364),對應!D:D,對應!E:E,"未對應") -> 3通路方案
A365: HQ關係人交易 | B365: 2025 | C365: 4 | D365: 通路方案 | E365: Other | F365: -2030 | G365: Other | H365: =_xlfn.XLOOKUP(TRIM(D365),對應!D:D,對應!E:E,"未對應") -> 3通路方案
A366: HQ關係人交易 | B366: 2025 | C366: 4 | D366: 通路方案 | E366: VGA | F366: -2000668480 | G366: 顯卡 | H366: =_xlfn.XLOOKUP(TRIM(D366),對應!D:D,對應!E:E,"未對應") -> 3通路方案
A367: HQ關係人交易 | B367: 2025 | C367: 4 | D367: _筆電+盈嘉 | E367: NB | F367: -1383117 | G367: 筆電 | H367: =_xlfn.XLOOKUP(TRIM(D367),對應!D:D,對應!E:E,"未對應") -> 4筆電+盈嘉
A368: HQ關係人交易 | B368: 2025 | C368: 5 | D368: _筆電+盈嘉 | E368: NB | F368: -24392935 | G368: 筆電 | H368: =_xlfn.XLOOKUP(TRIM(D368),對應!D:D,對應!E:E,"未對應") -> 4筆電+盈嘉
A369: HQ關係人交易 | B369: 2025 | C369: 5 | D369: 通路方案 | E369: MB | F369: -325635857 | G369: 主板 | H369: =_xlfn.XLOOKUP(TRIM(D369),對應!D:D,對應!E:E,"未對應") -> 3通路方案
A370: HQ關係人交易 | B370: 2025 | C370: 5 | D370: 通路方案 | E370: MONITOR | F370: -5813875 | G370: 螢幕 | H370: =_xlfn.XLOOKUP(TRIM(D370),對應!D:D,對應!E:E,"未對應") -> 3通路方案
A371: HQ關係人交易 | B371: 2025 | C371: 5 | D371: 通路方案 | E371: PC System | F371: 32017 | G371: 專案電腦 | H371: =_xlfn.XLOOKUP(TRIM(D371),對應!D:D,對應!E:E,"未對應") -> 3通路方案
A372: HQ關係人交易 | B372: 2025 | C372: 5 | D372: 通路方案 | E372: SSD | F372: -80298 | G372: 主板 | H372: =_xlfn.XLOOKUP(TRIM(D372),對應!D:D,對應!E:E,"未對應") -> 3通路方案
...

Sheet 對應
D1: 合併事業群 | E1: 新事業群
D2: 網通+技鋼 | E2: 1網通+技鋼 | L2: IFERROR(VLOOKUP(H2,對應!A:B,2,0),"")
D3: 技宸 | E3: 2技宸
A4: QUADRO | B4: 顯卡 | D4: 通路方案 | E4: 3通路方案
A5: VGA | B5: 顯卡 | D5: 筆電+盈嘉 | E5: 4筆電+盈嘉
A6: MONITOR | B6: 螢幕 | D6: _筆電+盈嘉 | E6: 4筆電+盈嘉
A7: NB | B7: 筆電 | D7: 百事益 | E7: 5百事益
A8: AI TOP | B8: 專案電腦 | D8: 雲城 | E8: 6雲城
A9: Case | B9: 專案電腦 | D9: 其他 | E9: 7製造
A10: CPU COOLER | B10: 專案電腦 | D10: _其他 | E10: 7製造
A11: PC System | B11: 專案電腦
A12: PSU | B12: 專案電腦
A13: BRIX | B13: 主板
A14: DRAM | B14: 主板
A15: MB | B15: 主板
A16: MM | B16: 主板
A17: SSD | B17: 主板
A18: Other | B18: Other
